Workbook

Sheet Summering
A1: Michel Zitron - Upphovsmanna andel | B1: (SEK)
B3: Total andel | C3: Stim | D3: BMG | E3: Kobalt
A4: Don´t You Worry Child | B4: =SUM(C4:E4) -> 4743409 | C4: =SUMIF(STIM!$B$6:$B$179,"Don´t You Worry Child*",STIM!$C$6:$C$179) -> 2195329 | D4: =SUMIF('BMG Rights'!$B$6:$B$34,"Don´t You Worry Child*",'BMG Rights'!$C$6:$C$34) -> 2548080 | E4: =0 -> 0
A5: Save the World | B5: =SUM(C5:E5) -> 631314 | C5: =SUMIF(STIM!$B$6:$B$179,"Save the World",STIM!$C$6:$C$179) -> 217074 | D5: =SUMIF('BMG Rights'!$B$6:$B$34,"Save the World",'BMG Rights'!$C$6:$C$34) -> 414240 | E5: =0 -> 0
A6: Reload (Free Love) | B6: =SUM(C6:E6) -> 157530 | C6: =SUMIF(STIM!$B$6:$B$179,"Reload (Free Love)",STIM!$C$6:$C$179) -> 71889 | D6: =SUMIF('BMG Rights'!$B$6:$B$34,"*Free Love*",'BMG Rights'!$C$6:$C$34) -> 0 | E6: =SUMIF(Kobalt!$B$6:$B$30,"*Free Love*",Kobalt!$C$6:$C$30) -> 85641
A7: Fade into Darkness | B7: =SUM(C7:E7) -> 35392 | C7: =SUMIF(STIM!$B$6:$B$179,"Fade into Darkness",STIM!$C$6:$C$179) -> 20612 | D7: =SUMIF('BMG Rights'!$B$6:$B$34,"Fade into Darkness",'BMG Rights'!$C$6:$C$34) -> 14780 | E7: =0 -> 0
A8: Reload (instrumental) | B8: =SUM(C8:E8) -> 0 | C8: =SUMIF(STIM!$B$6:$B$179,"Reload (instrumental)",STIM!$C$6:$C$179) -> 0 | D8: =0 -> 0 | E8: =0 -> 0
A10: Total | B10: =SUM(B4:B8) -> 5567645 | C10: =SUM(C4:C8) -> 2504904 | D10: =SUM(D4:D8) -> 2977100 | E10: =SUM(E4:E8) -> 85641
A11: 79% (MZ del av katalogens värde) | B11: =B10*0.79 -> 4398439.5 | C11: =C10*0.79 -> 1978874.2 | D11: =D10*0.79 -> 2351909 | E11: =E10*0.79 -> 67656.39
A12: Snitt 3 år | B12: =B11/3 -> 1466146.5
A13: Multiple | B13: 12
A14: Totalt 3 år (Multipel) | B14: =B12*B13 -> 17593758

Sheet Blad1

Sheet STIM
A1: Michel Zitron - Upphovsmanna andel
A4: STIM: (SEK)
A6: 44614 | B6: Don´t You Worry Child | C6: 0
B7: Save the World | C7: 0
B8: Reload (Free Love) | C8: 0
B9: Fade into Darkness | C9: 0
A10: 44614 | B10: =B6 -> Don´t You Worry Child | C10: 0
B11: =B7 -> Save the World | C11: 0
B12: =B8 -> Reload (Free Love) | C12: 0
B13: =B9 -> Fade into Darkness | C13: 0
A14: 44635 | B14: =B10 -> Don´t You Worry Child | C14: 0
B15: =B11 -> Save the World | C15: 0
B16: =B12 -> Reload (Free Love) | C16: 0
B17: =B13 -> Fade into Darkness | C17: 0
A18: 44698 | B18: =B14 -> Don´t You Worry Child | C18: 0
B19: =B15 -> Save the World | C19: 0
B20: =B16 -> Reload (Free Love) | C20: 0
B21: =B17 -> Fade into Darkness | C21: 0
A22: 44698 | B22: =B18 -> Don´t You Worry Child | C22: 0
B23: =B19 -> Save the World | C23: 0
B24: =B20 -> Reload (Free Love) | C24: 0
B25: =B21 -> Fade into Darkness | C25: 0
A26: 44728 | B26: =B18 -> Don´t You Worry Child | C26: 0
B27: =B19 -> Save the World | C27: 0
B28: =B20 -> Reload (Free Love) | C28: 0
B29: =B21 -> Fade into Darkness | C29: 0
A30: 44796 | B30: =B26 -> Don´t You Worry Child | C30: 0
B31: =B27 -> Save the World | C31: 0
B32: =B28 -> Reload (Free Love) | C32: 0
B33: =B29 -> Fade into Darkness | C33: 0
A34: 44796 | B34: =B30 -> Don´t You Worry Child | C34: 0
B35: =B31 -> Save the World | C35: 0
B36: =B32 -> Reload (Free Love) | C36: 0
B37: =B33 -> Fade into Darkness | C37: 0
A38: 44824 | B38: =B26 -> Don´t You Worry Child | C38: 0
B39: =B27 -> Save the World | C39: 0
B40: =B28 -> Reload (Free Love) | C40: 0
B41: =B29 -> Fade into Darkness | C41: 0
A42: 44852 | B42: =B38 -> Don´t You Worry Child | C42: 0
B43: =B39 -> Save the World | C43: 0
...

Sheet BMG Rights
A1: Michel Zitron - Upphovsmanna andel
A3: BMG Rights (SEK)
A6: 12/2022 | B6: Don´t You Worry Child | C6: 448900
B7: Save the World | C7: 61320
B8: Reload /Free Love) | C8: 0
B9: Fade into Darkness | C9: 3290
A11: 06/2023 | B11: =B6 -> Don´t You Worry Child | C11: 398620
B12: =B7 -> Save the World | C12: 53780
B13: =B8 -> Reload /Free Love) | C13: 0
B14: =B9 -> Fade into Darkness | C14: 1550
A16: 12/2023 | B16: =B11 -> Don´t You Worry Child | C16: 420170
B17: =B12 -> Save the World | C17: 139260
B18: =B13 -> Reload /Free Love) | C18: 0
B19: =B14 -> Fade into Darkness | C19: 2610
A21: 06/2024 | B21: =B16 -> Don´t You Worry Child | C21: 556820
B22: =B17 -> Save the World | C22: 67140
B23: =B18 -> Reload /Free Love) | C23: 0
B24: =B19 -> Fade into Darkness | C24: 3610
A26: 12/2024 | B26: =B21 -> Don´t You Worry Child | C26: 407270
B27: =B22 -> Save the World | C27: 52330
B28: =B23 -> Reload /Free Love) | C28: 0
B29: =B24 -> Fade into Darkness | C29: 2120
A31: 06/2025 | B31: =B26 -> Don´t You Worry Child | C31: 316300
B32: =B27 -> Save the World | C32: 40410
B33: =B28 -> Reload /Free Love) | C33: 0
B34: =B29 -> Fade into Darkness | C34: 1600

Sheet Kobalt
A1: Michel Zitron - Upphovsmanna andel
A3: Kobalt (SEK)
A6: Q1 2023 | B6: Reload /Free Love) | C6: 8611
A7: Q2 2023 | B7: Reload /Free Love) | C7: 7104
A8: Q3 2023 | B8: Reload /Free Love) | C8: 5698
A9: Q4 2023 | B9: Reload /Free Love) | C9: 7058
C10: 0
A11: II/2019 | B11: =B6 -> Reload /Free Love)
B12: =B7 -> Reload /Free Love) | J12: 2019: 23 140.66
B13: =B8 -> Reload /Free Love) | J13: 2020: 18 351.03
B14: =B9 -> Reload /Free Love) | J14: 2021: 23 422.48
A16: Q1 2024 | B16: =B11 -> Reload /Free Love) | C16: 8397
A17: Q2 2024 | B17: =B12 -> Reload /Free Love) | C17: 6514
A18: Q3 2024 | B18: =B13 -> Reload /Free Love) | C18: 5424
A19: Q4 2024 | B19: =B14 -> Reload /Free Love) | C19: 6588
C20: 0
A21: II/2020 | B21: =B16 -> Reload /Free Love)
B22: =B17 -> Reload /Free Love)
B23: =B18 -> Reload /Free Love) | C23: 0
B24: =B19 -> Reload /Free Love) | C24: 3170
A26: Q1 2025 | B26: =B21 -> Reload /Free Love) | C26: 6440
A27: Q2 2025 | B27: =B22 -> Reload /Free Love) | C27: 3935
A28: Q3 2025 | B28: =B23 -> Reload /Free Love) | C28: 8350
A29: Q4 2025 | B29: =B24 -> Reload /Free Love) | C29: 8352
C30: 0
B31: TOTAL | C31: =SUM(C6:C30) -> 85641
